<mujoco model="boxBot">
    <compiler angle="radian" meshdir="./meshes/gripper/" coordinate="local" />
    <size njmax="500" nconmax="100" />
    <asset>
        <mesh name="gripper_link_collision" file="gripper_link_collision.stl" />
        <mesh name="gripper_ta11_finger" file="gripper_finger_ta11_link.stl" />
    </asset>
    <worldbody>
        <geom size="0.275 0.275 0.275" type="box" rgba="0.3 0.3 0.3 0.2" />
        <body name="arm" pos="-0.15 0 0.33">
            <inertial pos="0.0124416 0.000111753 0.000108228" quat="-0.050236 0.703927 -0.0435733 0.707152" mass="1.60266" diaginertia="1.00144 1.0011 1.00067" />
            <geom quat="0.500048 0.5 -0.499952 -0.5" type="mesh" rgba="1 1 1 0.2" mesh="gripper_link_collision" />

            <body name="gripper_right_finger_link" pos="0 0 0" euler="1.57 -1.57 0">
                <inertial pos="-0.00447 0.010766 -0.121013" quat="0.944415 0.0576483 0.0941322 -0.309671" mass="0.10998" diaginertia="0.000161667 0.000161667 0.000161667" />
                <joint name="gripper_right_finger_joint" pos="0 0 0" axis="1 0 0" type="slide" limited="true" range="0 0.043" />

                <geom size="0.005 0.025 0.055" pos="0 0 0" quat="0 0 0 1" type="mesh" mesh="gripper_ta11_finger" rgba="0.7 0.7 0.7 1" />
            </body>

            <body name="gripper_left_finger_link" pos="0 0 0" euler="-1.57 -1.57 0">
                <inertial pos="-0.00447 0.010766 -0.121013" quat="0.424708 0.17592 -0.339851 0.820473" mass="0.10998" diaginertia="0.001 0.001 0.001" />
                <joint name="gripper_left_finger_joint" pos="0 0 0" axis="-1 0 0" type="slide" limited="true" range="0 0.043" damping="80" />

                <geom size="0.005 0.025 0.055" pos="0 0 0" quat="0 0 0 1" type="mesh" mesh="gripper_ta11_finger" rgba="0.7 0.7 0.7 1" />
            </body>
        </body>
    </worldbody>

    <!-- <contact>
        <exclude body1="arm" body2="gripper_right_finger_link" />
        <exclude body1="arm" body2="gripper_left_finger_link" />
        <exclude body1="gripper_right_finger_link" body2="gripper_left_finger_link" />
    </contact> -->

    <actuator>
        <position name="gripper_left_finger" joint="gripper_left_finger_joint" ctrlrange="0.0 0.043"></position>
        <position name="gripper_right_finger" joint="gripper_right_finger_joint" ctrlrange="0.0 0.043"></position>
    </actuator>

</mujoco>
